Workbook

Sheet Parceiros
A1: Nome Parceiro | B1: CPF | C1: Celular Contato/Whatsapp | D1: Outros Fones | E1: EMAIL
A2: Marcelo Vida Toda | B2: 020.729.899-81 | C2: 14 99136-1026 | E2: marcelowseibert@gmail.com
A3: Alexandre Mello | B3: 949.757.369-34 | C3: 49 99107-1232 | E3: alexandre_mello1@hotmail.com
A4: Juliana Faria | B4: 230.482.188-07 | C4: 18 99681-6394 | E4: juliana@rradvocacia.com
A5: Alex Borges | C5: 18 99786-0033 | E5: alex.abl@outlook.com
A6: Juliana Faria RR advocacia | C6: 18- 99681-6394 | D6: 18- 99149-5411 | E6: juliana@rradvocacia.com
A7: Leandro RR advocacia | C7: 18- 99645-4246 | D7: 18- 3653- 7733 | E7: leandro@rradvocacia.com
A8: Marcelo Slongo | E8: marceloslongoadv@hotmail.com
A9: Fernanda Bristot Correa | B9: 047.226.089-89 | E9: fernandacorrea_adv@hotmail.com
A10: Zé Maria

Sheet Contratos
A1: Nome Parceiro | B1: Ação | C1: Acordo ADV/Parceiro (por escrito)

Sheet Cálculos Enviados
A1: Cliente | B1: CPF Cliente | C1: Data Envio Email | D1: Destinatário 1 | E1: Destinatário 2 | F1: Destinatário 3 | G1: Parceria | H1: Chefe | I1: Data Retorno(Distribuição) | J1: O Que Retornou
A2: Oscar Vitorio Tretto | B2: 247.512.780-53 | C2: 45072 | D2: alexandre_mello1@hotmail.com | G2: =CONCAT('Cálculos Enviados'!$D2," | ",'Cálculos Enviados'!$E2," | ",'Cálculos Enviados'!$F2) -> #NAME? | H2: Alexandre Mello | J2: =VLOOKUP('Cálculos Enviados'!$B2,$M$2:$M$10,1,0) -> #N/A | M2: 006.071.568-56 | N2: 5001399-63.2023.4.03.6107
A3: Neri Ribeiro Jovenal | B3: 219.420.990-53 | C3: 45072 | D3: alexandre_mello1@hotmail.com | G3: =CONCAT('Cálculos Enviados'!$D3," | ",'Cálculos Enviados'!$E3," | ",'Cálculos Enviados'!$F3) -> #NAME? | H3: Alexandre Mello | J3: =VLOOKUP('Cálculos Enviados'!$B3,$M$2:$M$10,1,0) -> #N/A | M3: 059.567.368-60 | N3: 5001377-05.2023.4.03.6107
A4: Jose Carlos Gama | B4: 804.728.698-68 | C4: 45071 | D4: marcelowseibert@gmail.com | G4: =CONCAT('Cálculos Enviados'!$D4," | ",'Cálculos Enviados'!$E4," | ",'Cálculos Enviados'!$F4) -> #NAME? | H4: Marcelo | I4: 45084 | J4: =VLOOKUP('Cálculos Enviados'!$B4,$M$2:$M$10,1,0) -> 804.728.698-68 | M4: 080.435.368-99 | N4: 5005172-26.2023.4.03.6331
A5: Mirto Barbeiro Marine | B5: 704.619.708-30 | C5: 45071 | D5: marcelowseibert@gmail.com | G5: =CONCAT('Cálculos Enviados'!$D5," | ",'Cálculos Enviados'!$E5," | ",'Cálculos Enviados'!$F5) -> #NAME? | H5: Marcelo | I5: 45083 | J5: =VLOOKUP('Cálculos Enviados'!$B5,$M$2:$M$10,1,0) -> 704.619.708-30 | M5: 293.684.128-39 | N5: 5005072-71.2023.4.03.6331
A6: Fátima de Oliveira Rodrigues | B6: 293.684.128-39 | C6: 45071 | D6: alex.abl@outlook.com | G6: =CONCAT('Cálculos Enviados'!$D6," | ",'Cálculos Enviados'!$E6," | ",'Cálculos Enviados'!$F6) -> #NAME? | H6: Alex Borges | I6: 45076 | J6: =VLOOKUP('Cálculos Enviados'!$B6,$M$2:$M$10,1,0) -> 293.684.128-39 | M6: 704.619.708-30 | N6: 5001403-03.2023.4.03.6107
A7: Gilberto Moser | B7: 256.826.280-04 | C7: 45071 | D7: marcelowseibert@gmail.com | E7: alexandre_mello1@hotmail.com | G7: =CONCAT('Cálculos Enviados'!$D7," | ",'Cálculos Enviados'!$E7," | ",'Cálculos Enviados'!$F7) -> #NAME? | H7: Alexandre Mello | J7: =VLOOKUP('Cálculos Enviados'!$B7,$M$2:$M$10,1,0) -> #N/A | M7: 704.619.708-30 | N7: 0001022-65.2005.4.03.6316
A8: JOSE APARECIDO MORAES | B8: 059.567.368-60 | C8: 45079 | D8: marcelowseibert@gmail.com | E8: juliana@rradvocacia.com | F8: leandro@rradvocacia.com | G8: =CONCAT('Cálculos Enviados'!$D8," | ",'Cálculos Enviados'!$E8," | ",'Cálculos Enviados'!$F8) -> #NAME? | H8: Zé Maria | I8: 45082 | J8: =VLOOKUP('Cálculos Enviados'!$B8,$M$2:$M$10,1,0) -> 059.567.368-60 | M8: 804.728.698-68 | N8: 5005199-09.2023.4.03.6331
A9: Cristiano Luiz Fagundes Mendonça | B9: 621.121.120-15 | C9: 45079 | D9: marcelowseibert@gmail.com | E9: alexandre_mello1@hotmail.com | G9: =CONCAT('Cálculos Enviados'!$D9," | ",'Cálculos Enviados'!$E9," | ",'Cálculos Enviados'!$F9) -> #NAME? | H9: Alexandre Mello | J9: =VLOOKUP('Cálculos Enviados'!$B9,$M$2:$M$10,1,0) -> #N/A | M9: 957.550.128-49 | N9: 5005207-83.2023.4.03.6331
A10: LADISLAU VALDECIR MARTINES | B10: 957.550.128-49 | C10: 45079 | D10: marcelowseibert@gmail.com | E10: juliana@rradvocacia.com | F10: leandro@rradvocacia.com | G10: =CONCAT('Cálculos Enviados'!$D10," | ",'Cálculos Enviados'!$E10," | ",'Cálculos Enviados'!$F10) -> #NAME? | H10: Zé Maria | I10: 45084 | J10: =VLOOKUP('Cálculos Enviados'!$B10,$M$2:$M$10,1,0) -> 957.550.128-49 | M10: 966.072.978-20 | N10: 5002561-48.2023.4.03.6316
A11: LUCIMAR ANTUNES CUELLAS | B11: 006.071.568-56 | C11: 45079 | D11: marcelowseibert@gmail.com | E11: juliana@rradvocacia.com | F11: leandro@rradvocacia.com | G11: =CONCAT('Cálculos Enviados'!$D11," | ",'Cálculos Enviados'!$E11," | ",'Cálculos Enviados'!$F11) -> #NAME? | H11: Zé Maria | I11: 45082 | J11: =VLOOKUP('Cálculos Enviados'!$B11,$M$2:$M$10,1,0) -> 006.071.568-56
A12: RAIMUNDO DA SILVA | B12: 080.435.368-99 | C12: 45079 | D12: marcelowseibert@gmail.com | E12: juliana@rradvocacia.com | F12: leandro@rradvocacia.com | G12: =CONCAT('Cálculos Enviados'!$D12," | ",'Cálculos Enviados'!$E12," | ",'Cálculos Enviados'!$F12) -> #NAME? | H12: Zé Maria | I12: 45082 | J12: =VLOOKUP('Cálculos Enviados'!$B12,$M$2:$M$10,1,0) -> 080.435.368-99
A13: LUIZ AQUILES DAL FORNO | B13: 173.703.610-04 | C13: 45083 | D13: marcelowseibert@gmail.com | E13: marceloslongoadv@hotmail.com | G13: =CONCAT('Cálculos Enviados'!$D13," | ",'Cálculos Enviados'!$E13," | ",'Cálculos Enviados'!$F13) -> #NAME? | H13: Rradvocacia | J13: =VLOOKUP('Cálculos Enviados'!$B13,$M$2:$M$10,1,0) -> #N/A
A14: JOSE TAVARES | B14: 966.072.978-20 | C14: 45084 | D14: marcelowseibert@gmail.com | E14: juliana@rradvocacia.com | F14: leandro@rradvocacia.com | G14: =CONCAT('Cálculos Enviados'!$D14," | ",'Cálculos Enviados'!$E14," | ",'Cálculos Enviados'!$F14) -> #NAME? | H14: Zé Maria | I14: 45089 | J14: =VLOOKUP('Cálculos Enviados'!$B14,$M$2:$M$10,1,0) -> 966.072.978-20
A15: MILQUIAS FIGUEIRA SILVA | B15: 252.298.697-04 | C15: 45084 | D15: marcelowseibert@gmail.com | E15: juliana@rradvocacia.com | F15: leandro@rradvocacia.com | G15: =CONCAT('Cálculos Enviados'!$D15," | ",'Cálculos Enviados'!$E15," | ",'Cálculos Enviados'!$F15) -> #NAME? | H15: Zé Maria | J15: =VLOOKUP('Cálculos Enviados'!$B15,$M$2:$M$10,1,0) -> #N/A
A16: NATALINO HORÁCIO BORGES | B16: 464.437.200-59 | C16: 45084 | D16: marcelowseibert@gmail.com | E16: fernandacorrea_adv@hotmail.com | F16: a3consultoria.contato@gmail.com | G16: =CONCAT('Cálculos Enviados'!$D16," | ",'Cálculos Enviados'!$E16," | ",'Cálculos Enviados'!$F16) -> #NAME? | H16: Fernanda Correa | J16: =VLOOKUP('Cálculos Enviados'!$B16,$M$2:$M$10,1,0) -> #N/A
A17: Afonso Doering | B17: 201.278.040-72 | C17: 45084 | D17: marcelowseibert@gmail.com | E17: alexandre_mello1@hotmail.com | G17: =CONCAT('Cálculos Enviados'!$D17," | ",'Cálculos Enviados'!$E17," | ",'Cálculos Enviados'!$F17) -> #NAME? | H17: Alexandre Mello | J17: =VLOOKUP('Cálculos Enviados'!$B17,$M$2:$M$10,1,0) -> #N/A
A18: Telma Elite Tente | B18: 235.183.750-91 | C18: 45084 | D18: marcelowseibert@gmail.com | G18: =CONCAT('Cálculos Enviados'!$D18," | ",'Cálculos Enviados'!$E18," | ",'Cálculos Enviados'!$F18) -> #NAME? | H18: Marcelo | J18: =VLOOKUP('Cálculos Enviados'!$B18,$M$2:$M$10,1,0) -> #N/A
A19: Vilmar Klava | B19: 934.776.198-20 | C19: 45084 | D19: marcelowseibert@gmail.com | E19: alexandre_mello1@hotmail.com | G19: =CONCAT('Cálculos Enviados'!$D19," | ",'Cálculos Enviados'!$E19," | ",'Cálculos Enviados'!$F19) -> #NAME? | H19: Alexandre Mello | J19: =VLOOKUP('Cálculos Enviados'!$B19,$M$2:$M$10,1,0) -> #N/A
A20: Ivo Dagios | B20: 193.128.579-91 | C20: 45084 | D20: marcelowseibert@gmail.com | E20: alexandre_mello1@hotmail.com | G20: =CONCAT('Cálculos Enviados'!$D20," | ",'Cálculos Enviados'!$E20," | ",'Cálculos Enviados'!$F20) -> #NAME? | H20: Alexandre Mello | J20: =VLOOKUP('Cálculos Enviados'!$B20,$M$2:$M$10,1,0) -> #N/A
A21: Paulo Martins de Mello | B21: 150.760.919-15 | C21: 45084 | D21: marcelowseibert@gmail.com | E21: alexandre_mello1@hotmail.com | G21: =CONCAT('Cálculos Enviados'!$D21," | ",'Cálculos Enviados'!$E21," | ",'Cálculos Enviados'!$F21) -> #NAME? | H21: Alexandre Mello | J21: =VLOOKUP('Cálculos Enviados'!$B21,$M$2:$M$10,1,0) -> #N/A
A22: Renato Bloncoski | B22: 410.479.319-15 | C22: 45084 | D22: marcelowseibert@gmail.com | E22: alexandre_mello1@hotmail.com | G22: =CONCAT('Cálculos Enviados'!$D22," | ",'Cálculos Enviados'!$E22," | ",'Cálculos Enviados'!$F22) -> #NAME? | H22: Alexandre Mello | J22: =VLOOKUP('Cálculos Enviados'!$B22,$M$2:$M$10,1,0) -> #N/A
A23: Mario Bonadmann | B23: 473.613.019-91 | C23: 45084 | D23: marcelowseibert@gmail.com | E23: alexandre_mello1@hotmail.com | G23: =CONCAT('Cálculos Enviados'!$D23," | ",'Cálculos Enviados'!$E23," | ",'Cálculos Enviados'!$F23) -> #NAME? | H23: Alexandre Mello | J23: =VLOOKUP('Cálculos Enviados'!$B23,$M$2:$M$10,1,0) -> #N/A
A24: José Luiz Rizzi | B24: 166.140.030-20 | C24: 45086 | D24: marcelowseibert@gmail.com | E24: alexandre_mello1@hotmail.com | G24: =CONCAT('Cálculos Enviados'!$D24," | ",'Cálculos Enviados'!$E24," | ",'Cálculos Enviados'!$F24) -> #NAME? | H24: Alexandre Mello | J24: =VLOOKUP('Cálculos Enviados'!$B24,$M$2:$M$10,1,0) -> #N/A
A25: Carmen Holanda | B25: 818.004.288-04 | C25: 45086 | D25: marcelowseibert@gmail.com | E25: alexandre_mello1@hotmail.com | G25: =CONCAT('Cálculos Enviados'!$D25," | ",'Cálculos Enviados'!$E25," | ",'Cálculos Enviados'!$F25) -> #NAME? | H25: Alexandre Mello | J25: =VLOOKUP('Cálculos Enviados'!$B25,$M$2:$M$10,1,0) -> #N/A
A26: Lotario Pereira dos Santos | B26: 325.476.500-10 | C26: 45086 | D26: marcelowseibert@gmail.com | E26: alexandre_mello1@hotmail.com | G26: =CONCAT('Cálculos Enviados'!$D26," | ",'Cálculos Enviados'!$E26," | ",'Cálculos Enviados'!$F26) -> #NAME? | H26: Alexandre Mello | J26: =VLOOKUP('Cálculos Enviados'!$B26,$M$2:$M$10,1,0) -> #N/A
A27: Maria Salete Sander | B27: 287.487.430-20 | C27: 45086 | D27: marcelowseibert@gmail.com | E27: alexandre_mello1@hotmail.com | G27: =CONCAT('Cálculos Enviados'!$D27," | ",'Cálculos Enviados'!$E27," | ",'Cálculos Enviados'!$F27) -> #NAME? | H27: Alexandre Mello | J27: =VLOOKUP('Cálculos Enviados'!$B27,$M$2:$M$10,1,0) -> #N/A
A28: Artidor Magalhães | B28: 209.234.300-91 | C28: 45086 | D28: marcelowseibert@gmail.com | E28: alexandre_mello1@hotmail.com | G28: =CONCAT('Cálculos Enviados'!$D28," | ",'Cálculos Enviados'!$E28," | ",'Cálculos Enviados'!$F28) -> #NAME? | H28: Alexandre Mello | J28: =VLOOKUP('Cálculos Enviados'!$B28,$M$2:$M$10,1,0) -> #N/A
A29: Corinta Maria Teixeira Martins | B29: 556.385.110-91 | C29: 45091 | D29: alexandre_mello1@hotmail.com | G29: =CONCAT('Cálculos Enviados'!$D29," | ",'Cálculos Enviados'!$E29," | ",'Cálculos Enviados'!$F29) -> #NAME? | H29: Alexandre Mello | J29: =VLOOKUP('Cálculos Enviados'!$B29,$M$2:$M$10,1,0) -> #N/A
A30: Luiza Antonia Andrade Pasetti | B30: 396.219.369-34 | C30: 45092 | D30: alexandre_mello1@hotmail.com | G30: =CONCAT('Cálculos Enviados'!$D30," | ",'Cálculos Enviados'!$E30," | ",'Cálculos Enviados'!$F30) -> #NAME? | H30: Alexandre Mello | J30: =VLOOKUP('Cálculos Enviados'!$B30,$M$2:$M$10,1,0) -> #N/A
A31: Dejanira Gonçalves Lustosa | B31: 518.589.249-87 | C31: 45103 | D31: marcelowseibert@gmail.com | E31: alexandre_mello1@hotmail.com | G31: =CONCAT('Cálculos Enviados'!$D31," | ",'Cálculos Enviados'!$E31," | ",'Cálculos Enviados'!$F31) -> #NAME? | H31: Alexandre Mello | J31: =VLOOKUP('Cálculos Enviados'!$B31,$M$2:$M$10,1,0) -> #N/A
A32: Fatima Noeli Ferreira | B32: 508.438.859-04 | C32: 45103 | D32: marcelowseibert@gmail.com | E32: alexandre_mello1@hotmail.com | G32: =CONCAT('Cálculos Enviados'!$D32," | ",'Cálculos Enviados'!$E32," | ",'Cálculos Enviados'!$F32) -> #NAME? | H32: Alexandre Mello | J32: =VLOOKUP('Cálculos Enviados'!$B32,$M$2:$M$10,1,0) -> #N/A
A33: Romeu Kerber | B33: 254.999.630-53 | C33: 45103 | D33: marcelowseibert@gmail.com | E33: alexandre_mello1@hotmail.com | G33: =CONCAT('Cálculos Enviados'!$D33," | ",'Cálculos Enviados'!$E33," | ",'Cálculos Enviados'!$F33) -> #NAME? | H33: Alexandre Mello | J33: =VLOOKUP('Cálculos Enviados'!$B33,$M$2:$M$10,1,0) -> #N/A
A34: Joel Antonio Rech Mattos | B34: 194.073.190-91 | C34: 45103 | D34: marcelowseibert@gmail.com | E34: alexandre_mello1@hotmail.com | G34: =CONCAT('Cálculos Enviados'!$D34," | ",'Cálculos Enviados'!$E34," | ",'Cálculos Enviados'!$F34) -> #NAME? | H34: Alexandre Mello | J34: =VLOOKUP('Cálculos Enviados'!$B34,$M$2:$M$10,1,0) -> #N/A
A35: Joaquim Valdeci dos Santos | B35: 614.560.710-68 | C35: 45103 | D35: marcelowseibert@gmail.com | E35: alexandre_mello1@hotmail.com | G35: =CONCAT('Cálculos Enviados'!$D35," | ",'Cálculos Enviados'!$E35," | ",'Cálculos Enviados'!$F35) -> #NAME? | H35: Alexandre Mello | J35: =VLOOKUP('Cálculos Enviados'!$B35,$M$2:$M$10,1,0) -> #N/A
A36: Jorge Tadeu da Silva | B36: 200.420.940-20 | C36: 45103 | D36: marcelowseibert@gmail.com | E36: alexandre_mello1@hotmail.com | G36: =CONCAT('Cálculos Enviados'!$D36," | ",'Cálculos Enviados'!$E36," | ",'Cálculos Enviados'!$F36) -> #NAME? | H36: Alexandre Mello | J36: =VLOOKUP('Cálculos Enviados'!$B36,$M$2:$M$10,1,0) -> #N/A
A37: Antonio Carlos Carrao Longhi | B37: 256.338.560-15 | C37: 45103 | D37: marcelowseibert@gmail.com | E37: alexandre_mello1@hotmail.com | G37: =CONCAT('Cálculos Enviados'!$D37," | ",'Cálculos Enviados'!$E37," | ",'Cálculos Enviados'!$F37) -> #NAME? | H37: Alexandre Mello | J37: =VLOOKUP('Cálculos Enviados'!$B37,$M$2:$M$10,1,0) -> #N/A
A38: Cirilo Biazussi | B38: 212.982.039-53 | C38: 45110 | D38: marcelowseibert@gmail.com | G38: =CONCAT('Cálculos Enviados'!$D38," | ",'Cálculos Enviados'!$E38," | ",'Cálculos Enviados'!$F38) -> #NAME? | H38: Marcelo | J38: =VLOOKUP('Cálculos Enviados'!$B38,$M$2:$M$10,1,0) -> #N/A
A39: Mario José Moraes | B39: 034.478.228-05 | C39: 45110 | D39: marcelowseibert@gmail.com | G39: =CONCAT('Cálculos Enviados'!$D39," | ",'Cálculos Enviados'!$E39," | ",'Cálculos Enviados'!$F39) -> #NAME? | H39: Marcelo | J39: =VLOOKUP('Cálculos Enviados'!$B39,$M$2:$M$10,1,0) -> #N/A
A40: ANESIO AUGUSTO DE OLIVEIRA | B40: 969.590.968-04 | C40: 45120 | D40: alex.abl@outlook.com | H40: Alex Borges
...

Sheet Resumo
A3: Rótulos de Linha | B3: Contagem de CPF Cliente
A4: Alex Borges | B4: 2
A5: Alexandre Mello | B5: 25
A6: Fernanda Correa | B6: 1
A7: M7 Assessoria | B7: 25
A8: Zé Maria | B8: 6
A9: Marcelo | B9: 5
A10: Rradvocacia | B10: 1
A11: Total Geral | B11: 65
